Workbook

Sheet Synthèse
A1: Budget prévisionnel de l'app Tic
A2: Hors droits d'auteur et main d'œuvre. Montants en euros TTC estimés.
A4: Catégorie | B4: Phase 1 : MVP | C4: Phase 2 : lancement | D4: Total
A5: Juridique & administratif | B5: =SUMIFS(Budget!$H$2:$H$40,Budget!$A$2:$A$40,$A5) -> 2640 | C5: =SUMIFS(Budget!$I$2:$I$40,Budget!$A$2:$A$40,$A5) -> 1320 | D5: =B5+C5 -> 3960
A6: Stores & comptes | B6: =SUMIFS(Budget!$H$2:$H$40,Budget!$A$2:$A$40,$A6) -> 205.64 | C6: =SUMIFS(Budget!$I$2:$I$40,Budget!$A$2:$A$40,$A6) -> 268.14 | D6: =B6+C6 -> 473.78
A7: Matériel de test | B7: =SUMIFS(Budget!$H$2:$H$40,Budget!$A$2:$A$40,$A7) -> 940 | C7: =SUMIFS(Budget!$I$2:$I$40,Budget!$A$2:$A$40,$A7) -> 200 | D7: =B7+C7 -> 1140
A8: Technique & hébergement | B8: =SUMIFS(Budget!$H$2:$H$40,Budget!$A$2:$A$40,$A8) -> 588.04 | C8: =SUMIFS(Budget!$I$2:$I$40,Budget!$A$2:$A$40,$A8) -> 4622.4 | D8: =B8+C8 -> 5210.44
A9: Contenu (hors droits) | B9: =SUMIFS(Budget!$H$2:$H$40,Budget!$A$2:$A$40,$A9) -> 300 | C9: =SUMIFS(Budget!$I$2:$I$40,Budget!$A$2:$A$40,$A9) -> 500 | D9: =B9+C9 -> 800
A10: Tests utilisateurs | B10: =SUMIFS(Budget!$H$2:$H$40,Budget!$A$2:$A$40,$A10) -> 300 | C10: =SUMIFS(Budget!$I$2:$I$40,Budget!$A$2:$A$40,$A10) -> 200 | D10: =B10+C10 -> 500
A11: Marketing & acquisition | B11: =SUMIFS(Budget!$H$2:$H$40,Budget!$A$2:$A$40,$A11) -> 390 | C11: =SUMIFS(Budget!$I$2:$I$40,Budget!$A$2:$A$40,$A11) -> 6380 | D11: =B11+C11 -> 6770
A12: Imprévus | B12: =Budget!H43 -> 536.368 | C12: =Budget!I43 -> 1349.054 | D12: =B12+C12 -> 1885.422
A13: TOTAL | B13: =SUM(B5:B12) -> 5900.048 | C13: =SUM(C5:C12) -> 14839.594 | D13: =SUM(D5:D12) -> 20739.642
A15: Coût mensuel moyen, phase 2 | B15: =C13/Hypothèses!$B$5 -> 1236.6328
A16: Durée des phases (mois) | B16: =Hypothèses!$B$4 -> 6 | C16: =Hypothèses!$B$5 -> 12

Sheet Hypothèses
A1: Hypothèses du budget
A2: Cellules en bleu = valeurs à ajuster. Tout le reste du classeur se recalcule.
A4: Durée phase 1 : MVP (mois) | B4: 6 | C4: Développement + tests utilisateurs, avant la sortie publique.
A5: Durée phase 2 : lancement (mois) | B5: 12 | C5: Première année après la sortie sur les stores.
A6: Taux de change (€ pour 1 $) | B6: 0.86 | C6: Hypothèse à mettre à jour avec le cours du jour ; sert aux services facturés en dollars.
A7: Marge pour imprévus | B7: 0.1 | C7: Pratique courante : 10 à 15 % du sous-total.
A10: Exclus de ce budget (à la demande) : droits d'auteur et licences musicales, main d'œuvre de l'équipe (salaires, rémunération des fondateurs).
A11: Hypothèse : l'équipe dispose déjà de ses ordinateurs (dont un Mac pour compiler l'app iOS).

Sheet Budget
A1: Catégorie | B1: Poste | C1: Coût unitaire | D1: Devise | E1: Fréquence | F1: Qté phase 1 | G1: Qté phase 2 | H1: Coût phase 1 (€) | I1: Coût phase 2 (€) | J1: Total (€) | K1: Source / hypothèse
A2: Juridique & administratif
A3: Juridique & administratif | B3: Création de la société (SAS, annonce légale, greffe) | C3: 250 | D3: € | E3: Unique | F3: 1 | G3: 0 | H3: =$C3*IF($D3="$",Hypothèses!$B$6,1)*$F3*IF($E3="Mensuel",Hypothèses!$B$4,IF($E3="Annuel",ROUNDUP(Hypothèses!$B$4/12,0),1)) -> 250 | I3: =$C3*IF($D3="$",Hypothèses!$B$6,1)*$G3*IF($E3="Mensuel",Hypothèses!$B$5,IF($E3="Annuel",ROUNDUP(Hypothèses!$B$5/12,0),1)) -> 0 | J3: =H3+I3 -> 250 | K3: Estimation via une plateforme juridique en ligne.
A4: Juridique & administratif | B4: Dépôt de marque INPI, 1re classe (classe 9, logiciels) | C4: 190 | D4: € | E4: Unique | F4: 1 | G4: 0 | H4: =$C4*IF($D4="$",Hypothèses!$B$6,1)*$F4*IF($E4="Mensuel",Hypothèses!$B$4,IF($E4="Annuel",ROUNDUP(Hypothèses!$B$4/12,0),1)) -> 190 | I4: =$C4*IF($D4="$",Hypothèses!$B$6,1)*$G4*IF($E4="Mensuel",Hypothèses!$B$5,IF($E4="Annuel",ROUNDUP(Hypothèses!$B$5/12,0),1)) -> 0 | J4: =H4+I4 -> 190 | K4: INPI : 190 € pour une classe (legalstart.fr).
A5: Juridique & administratif | B5: Classe supplémentaire (classe 41, enseignement) | C5: 40 | D5: € | E5: Unique | F5: 1 | G5: 0 | H5: =$C5*IF($D5="$",Hypothèses!$B$6,1)*$F5*IF($E5="Mensuel",Hypothèses!$B$4,IF($E5="Annuel",ROUNDUP(Hypothèses!$B$4/12,0),1)) -> 40 | I5: =$C5*IF($D5="$",Hypothèses!$B$6,1)*$G5*IF($E5="Mensuel",Hypothèses!$B$5,IF($E5="Annuel",ROUNDUP(Hypothèses!$B$5/12,0),1)) -> 0 | J5: =H5+I5 -> 40 | K5: INPI : 40 € par classe supplémentaire (legalstart.fr).
A6: Juridique & administratif | B6: Rédaction CGU, CGV et politique de confidentialité (RGPD) | C6: 1500 | D6: € | E6: Unique | F6: 1 | G6: 0 | H6: =$C6*IF($D6="$",Hypothèses!$B$6,1)*$F6*IF($E6="Mensuel",Hypothèses!$B$4,IF($E6="Annuel",ROUNDUP(Hypothèses!$B$4/12,0),1)) -> 1500 | I6: =$C6*IF($D6="$",Hypothèses!$B$6,1)*$G6*IF($E6="Mensuel",Hypothèses!$B$5,IF($E6="Annuel",ROUNDUP(Hypothèses!$B$5/12,0),1)) -> 0 | J6: =H6+I6 -> 1500 | K6: Estimation : forfait avocat ou plateforme juridique.
A7: Juridique & administratif | B7: Assurance responsabilité civile professionnelle | C7: 35 | D7: € | E7: Mensuel | F7: 1 | G7: 1 | H7: =$C7*IF($D7="$",Hypothèses!$B$6,1)*$F7*IF($E7="Mensuel",Hypothèses!$B$4,IF($E7="Annuel",ROUNDUP(Hypothèses!$B$4/12,0),1)) -> 210 | I7: =$C7*IF($D7="$",Hypothèses!$B$6,1)*$G7*IF($E7="Mensuel",Hypothèses!$B$5,IF($E7="Annuel",ROUNDUP(Hypothèses!$B$5/12,0),1)) -> 420 | J7: =H7+I7 -> 630 | K7: Estimation pour une jeune entreprise du numérique.
A8: Juridique & administratif | B8: Expert-comptable en ligne | C8: 60 | D8: € | E8: Mensuel | F8: 1 | G8: 1 | H8: =$C8*IF($D8="$",Hypothèses!$B$6,1)*$F8*IF($E8="Mensuel",Hypothèses!$B$4,IF($E8="Annuel",ROUNDUP(Hypothèses!$B$4/12,0),1)) -> 360 | I8: =$C8*IF($D8="$",Hypothèses!$B$6,1)*$G8*IF($E8="Mensuel",Hypothèses!$B$5,IF($E8="Annuel",ROUNDUP(Hypothèses!$B$5/12,0),1)) -> 720 | J8: =H8+I8 -> 1080 | K8: Estimation, offre en ligne pour SAS sans salarié.
A9: Juridique & administratif | B9: Compte bancaire professionnel | C9: 15 | D9: € | E9: Mensuel | F9: 1 | G9: 1 | H9: =$C9*IF($D9="$",Hypothèses!$B$6,1)*$F9*IF($E9="Mensuel",Hypothèses!$B$4,IF($E9="Annuel",ROUNDUP(Hypothèses!$B$4/12,0),1)) -> 90 | I9: =$C9*IF($D9="$",Hypothèses!$B$6,1)*$G9*IF($E9="Mensuel",Hypothèses!$B$5,IF($E9="Annuel",ROUNDUP(Hypothèses!$B$5/12,0),1)) -> 180 | J9: =H9+I9 -> 270 | K9: Estimation, banque en ligne.
A10: Stores & comptes
A11: Stores & comptes | B11: Apple Developer Program | C11: 99 | D11: $ | E11: Annuel | F11: 1 | G11: 1 | H11: =$C11*IF($D11="$",Hypothèses!$B$6,1)*$F11*IF($E11="Mensuel",Hypothèses!$B$4,IF($E11="Annuel",ROUNDUP(Hypothèses!$B$4/12,0),1)) -> 85.14 | I11: =$C11*IF($D11="$",Hypothèses!$B$6,1)*$G11*IF($E11="Mensuel",Hypothèses!$B$5,IF($E11="Annuel",ROUNDUP(Hypothèses!$B$5/12,0),1)) -> 85.14 | J11: =H11+I11 -> 170.28 | K11: 99 $/an (ilab.md, 2026).
A12: Stores & comptes | B12: Compte développeur Google Play | C12: 25 | D12: $ | E12: Unique | F12: 1 | G12: 0 | H12: =$C12*IF($D12="$",Hypothèses!$B$6,1)*$F12*IF($E12="Mensuel",Hypothèses!$B$4,IF($E12="Annuel",ROUNDUP(Hypothèses!$B$4/12,0),1)) -> 21.5 | I12: =$C12*IF($D12="$",Hypothèses!$B$6,1)*$G12*IF($E12="Mensuel",Hypothèses!$B$5,IF($E12="Annuel",ROUNDUP(Hypothèses!$B$5/12,0),1)) -> 0 | J12: =H12+I12 -> 21.5 | K12: 25 $ une seule fois (ilab.md, 2026).
A13: Stores & comptes | B13: Nom de domaine | C13: 15 | D13: € | E13: Annuel | F13: 1 | G13: 1 | H13: =$C13*IF($D13="$",Hypothèses!$B$6,1)*$F13*IF($E13="Mensuel",Hypothèses!$B$4,IF($E13="Annuel",ROUNDUP(Hypothèses!$B$4/12,0),1)) -> 15 | I13: =$C13*IF($D13="$",Hypothèses!$B$6,1)*$G13*IF($E13="Mensuel",Hypothèses!$B$5,IF($E13="Annuel",ROUNDUP(Hypothèses!$B$5/12,0),1)) -> 15 | J13: =H13+I13 -> 30 | K13: Estimation, .fr ou .app.
A14: Stores & comptes | B14: Messagerie pro (par utilisateur) | C14: 7 | D14: € | E14: Mensuel | F14: 2 | G14: 2 | H14: =$C14*IF($D14="$",Hypothèses!$B$6,1)*$F14*IF($E14="Mensuel",Hypothèses!$B$4,IF($E14="Annuel",ROUNDUP(Hypothèses!$B$4/12,0),1)) -> 84 | I14: =$C14*IF($D14="$",Hypothèses!$B$6,1)*$G14*IF($E14="Mensuel",Hypothèses!$B$5,IF($E14="Annuel",ROUNDUP(Hypothèses!$B$5/12,0),1)) -> 168 | J14: =H14+I14 -> 252 | K14: Estimation, 2 comptes.
A15: Matériel de test
A16: Matériel de test | B16: Clavier MIDI 61 touches | C16: 150 | D16: € | E16: Unique | F16: 2 | G16: 0 | H16: =$C16*IF($D16="$",Hypothèses!$B$6,1)*$F16*IF($E16="Mensuel",Hypothèses!$B$4,IF($E16="Annuel",ROUNDUP(Hypothèses!$B$4/12,0),1)) -> 300 | I16: =$C16*IF($D16="$",Hypothèses!$B$6,1)*$G16*IF($E16="Mensuel",Hypothèses!$B$5,IF($E16="Annuel",ROUNDUP(Hypothèses!$B$5/12,0),1)) -> 0 | J16: =H16+I16 -> 300 | K16: Estimation, modèle d'entrée de gamme.
A17: Matériel de test | B17: Adaptateurs et câbles USB-MIDI | C17: 30 | D17: € | E17: Unique | F17: 3 | G17: 0 | H17: =$C17*IF($D17="$",Hypothèses!$B$6,1)*$F17*IF($E17="Mensuel",Hypothèses!$B$4,IF($E17="Annuel",ROUNDUP(Hypothèses!$B$4/12,0),1)) -> 90 | I17: =$C17*IF($D17="$",Hypothèses!$B$6,1)*$G17*IF($E17="Mensuel",Hypothèses!$B$5,IF($E17="Annuel",ROUNDUP(Hypothèses!$B$5/12,0),1)) -> 0 | J17: =H17+I17 -> 90 | K17: Estimation.
A18: Matériel de test | B18: iPhone de test reconditionné | C18: 350 | D18: € | E18: Unique | F18: 1 | G18: 0 | H18: =$C18*IF($D18="$",Hypothèses!$B$6,1)*$F18*IF($E18="Mensuel",Hypothèses!$B$4,IF($E18="Annuel",ROUNDUP(Hypothèses!$B$4/12,0),1)) -> 350 | I18: =$C18*IF($D18="$",Hypothèses!$B$6,1)*$G18*IF($E18="Mensuel",Hypothèses!$B$5,IF($E18="Annuel",ROUNDUP(Hypothèses!$B$5/12,0),1)) -> 0 | J18: =H18+I18 -> 350 | K18: Estimation.
A19: Matériel de test | B19: Smartphone Android de test | C19: 200 | D19: € | E19: Unique | F19: 1 | G19: 0 | H19: =$C19*IF($D19="$",Hypothèses!$B$6,1)*$F19*IF($E19="Mensuel",Hypothèses!$B$4,IF($E19="Annuel",ROUNDUP(Hypothèses!$B$4/12,0),1)) -> 200 | I19: =$C19*IF($D19="$",Hypothèses!$B$6,1)*$G19*IF($E19="Mensuel",Hypothèses!$B$5,IF($E19="Annuel",ROUNDUP(Hypothèses!$B$5/12,0),1)) -> 0 | J19: =H19+I19 -> 200 | K19: Estimation, entrée de gamme.
A20: Matériel de test | B20: Guitare d'étude (préparation V2 guitare) | C20: 200 | D20: € | E20: Unique | F20: 0 | G20: 1 | H20: =$C20*IF($D20="$",Hypothèses!$B$6,1)*$F20*IF($E20="Mensuel",Hypothèses!$B$4,IF($E20="Annuel",ROUNDUP(Hypothèses!$B$4/12,0),1)) -> 0 | I20: =$C20*IF($D20="$",Hypothèses!$B$6,1)*$G20*IF($E20="Mensuel",Hypothèses!$B$5,IF($E20="Annuel",ROUNDUP(Hypothèses!$B$5/12,0),1)) -> 200 | J20: =H20+I20 -> 200 | K20: Estimation ; achat en phase 2.
A21: Technique & hébergement
A22: Technique & hébergement | B22: Backend Supabase (base, comptes, stockage) | C22: 25 | D22: $ | E22: Mensuel | F22: 0 | G22: 1 | H22: =$C22*IF($D22="$",Hypothèses!$B$6,1)*$F22*IF($E22="Mensuel",Hypothèses!$B$4,IF($E22="Annuel",ROUNDUP(Hypothèses!$B$4/12,0),1)) -> 0 | I22: =$C22*IF($D22="$",Hypothèses!$B$6,1)*$G22*IF($E22="Mensuel",Hypothèses!$B$5,IF($E22="Annuel",ROUNDUP(Hypothèses!$B$5/12,0),1)) -> 258 | J22: =H22+I22 -> 258 | K22: Gratuit en phase 1 ; plan Pro 25 $/mois ensuite (makerkit.dev, 2026).
A23: Technique & hébergement | B23: Stockage et diffusion des fichiers audio (CDN) | C23: 10 | D23: € | E23: Mensuel | F23: 0 | G23: 1 | H23: =$C23*IF($D23="$",Hypothèses!$B$6,1)*$F23*IF($E23="Mensuel",Hypothèses!$B$4,IF($E23="Annuel",ROUNDUP(Hypothèses!$B$4/12,0),1)) -> 0 | I23: =$C23*IF($D23="$",Hypothèses!$B$6,1)*$G23*IF($E23="Mensuel",Hypothèses!$B$5,IF($E23="Annuel",ROUNDUP(Hypothèses!$B$5/12,0),1)) -> 120 | J23: =H23+I23 -> 120 | K23: Estimation, accompagnements et partitions.
A24: Technique & hébergement | B24: IA : génération des parcours et transcriptions | C24: 50 | D24: € | E24: Mensuel | F24: 1 | G24: 0 | H24: =$C24*IF($D24="$",Hypothèses!$B$6,1)*$F24*IF($E24="Mensuel",Hypothèses!$B$4,IF($E24="Annuel",ROUNDUP(Hypothèses!$B$4/12,0),1)) -> 300 | I24: =$C24*IF($D24="$",Hypothèses!$B$6,1)*$G24*IF($E24="Mensuel",Hypothèses!$B$5,IF($E24="Annuel",ROUNDUP(Hypothèses!$B$5/12,0),1)) -> 0 | J24: =H24+I24 -> 300 | K24: Estimation, volume de tests en phase 1.
A25: Technique & hébergement | B25: IA : génération des parcours et transcriptions (production) | C25: 300 | D25: € | E25: Mensuel | F25: 0 | G25: 1 | H25: =$C25*IF($D25="$",Hypothèses!$B$6,1)*$F25*IF($E25="Mensuel",Hypothèses!$B$4,IF($E25="Annuel",ROUNDUP(Hypothèses!$B$4/12,0),1)) -> 0 | I25: =$C25*IF($D25="$",Hypothèses!$B$6,1)*$G25*IF($E25="Mensuel",Hypothèses!$B$5,IF($E25="Annuel",ROUNDUP(Hypothèses!$B$5/12,0),1)) -> 3600 | J25: =H25+I25 -> 3600 | K25: Estimation, dépend du nombre d'utilisateurs.
A26: Technique & hébergement | B26: Service de compilation et publication de l'app | C26: 19 | D26: $ | E26: Mensuel | F26: 1 | G26: 1 | H26: =$C26*IF($D26="$",Hypothèses!$B$6,1)*$F26*IF($E26="Mensuel",Hypothèses!$B$4,IF($E26="Annuel",ROUNDUP(Hypothèses!$B$4/12,0),1)) -> 98.04 | I26: =$C26*IF($D26="$",Hypothèses!$B$6,1)*$G26*IF($E26="Mensuel",Hypothèses!$B$5,IF($E26="Annuel",ROUNDUP(Hypothèses!$B$5/12,0),1)) -> 196.08 | J26: =H26+I26 -> 294.12 | K26: Tarif indicatif d'un service de build mobile, à vérifier.
A27: Technique & hébergement | B27: Suivi des erreurs (crash reporting) | C27: 26 | D27: $ | E27: Mensuel | F27: 0 | G27: 1 | H27: =$C27*IF($D27="$",Hypothèses!$B$6,1)*$F27*IF($E27="Mensuel",Hypothèses!$B$4,IF($E27="Annuel",ROUNDUP(Hypothèses!$B$4/12,0),1)) -> 0 | I27: =$C27*IF($D27="$",Hypothèses!$B$6,1)*$G27*IF($E27="Mensuel",Hypothèses!$B$5,IF($E27="Annuel",ROUNDUP(Hypothèses!$B$5/12,0),1)) -> 268.32 | J27: =H27+I27 -> 268.32 | K27: Gratuit en phase 1 ; tarif indicatif d'un plan équipe, à vérifier.
A28: Technique & hébergement | B28: Gestion des abonnements (RevenueCat) | C28: 0 | D28: $ | E28: Mensuel | F28: 1 | G28: 1 | H28: =$C28*IF($D28="$",Hypothèses!$B$6,1)*$F28*IF($E28="Mensuel",Hypothèses!$B$4,IF($E28="Annuel",ROUNDUP(Hypothèses!$B$4/12,0),1)) -> 0 | I28: =$C28*IF($D28="$",Hypothèses!$B$6,1)*$G28*IF($E28="Mensuel",Hypothèses!$B$5,IF($E28="Annuel",ROUNDUP(Hypothèses!$B$5/12,0),1)) -> 0 | J28: =H28+I28 -> 0 | K28: Gratuit jusqu'à 2 500 $ de revenus suivis par mois, puis 1 % (dodopayments.com).
A29: Technique & hébergement | B29: Banque de sons de piano (licence de samples) | C29: 100 | D29: € | E29: Unique | F29: 1 | G29: 0 | H29: =$C29*IF($D29="$",Hypothèses!$B$6,1)*$F29*IF($E29="Mensuel",Hypothèses!$B$4,IF($E29="Annuel",ROUNDUP(Hypothèses!$B$4/12,0),1)) -> 100 | I29: =$C29*IF($D29="$",Hypothèses!$B$6,1)*$G29*IF($E29="Mensuel",Hypothèses!$B$5,IF($E29="Annuel",ROUNDUP(Hypothèses!$B$5/12,0),1)) -> 0 | J29: =H29+I29 -> 100 | K29: Estimation, licence commerciale.
A30: Technique & hébergement | B30: Outil de design (1 éditeur) | C30: 15 | D30: € | E30: Mensuel | F30: 1 | G30: 1 | H30: =$C30*IF($D30="$",Hypothèses!$B$6,1)*$F30*IF($E30="Mensuel",Hypothèses!$B$4,IF($E30="Annuel",ROUNDUP(Hypothèses!$B$4/12,0),1)) -> 90 | I30: =$C30*IF($D30="$",Hypothèses!$B$6,1)*$G30*IF($E30="Mensuel",Hypothèses!$B$5,IF($E30="Annuel",ROUNDUP(Hypothèses!$B$5/12,0),1)) -> 180 | J30: =H30+I30 -> 270 | K30: Tarif indicatif, à vérifier.
A31: Contenu (hors droits)
A32: Contenu (hors droits) | B32: Micro et interface audio (enregistrer les accompagnements) | C32: 300 | D32: € | E32: Unique | F32: 1 | G32: 0 | H32: =$C32*IF($D32="$",Hypothèses!$B$6,1)*$F32*IF($E32="Mensuel",Hypothèses!$B$4,IF($E32="Annuel",ROUNDUP(Hypothèses!$B$4/12,0),1)) -> 300 | I32: =$C32*IF($D32="$",Hypothèses!$B$6,1)*$G32*IF($E32="Mensuel",Hypothèses!$B$5,IF($E32="Annuel",ROUNDUP(Hypothèses!$B$5/12,0),1)) -> 0 | J32: =H32+I32 -> 300 | K32: Estimation.
A33: Contenu (hors droits) | B33: Location de studio ponctuelle | C33: 250 | D33: € | E33: Unique | F33: 0 | G33: 2 | H33: =$C33*IF($D33="$",Hypothèses!$B$6,1)*$F33*IF($E33="Mensuel",Hypothèses!$B$4,IF($E33="Annuel",ROUNDUP(Hypothèses!$B$4/12,0),1)) -> 0 | I33: =$C33*IF($D33="$",Hypothèses!$B$6,1)*$G33*IF($E33="Mensuel",Hypothèses!$B$5,IF($E33="Annuel",ROUNDUP(Hypothèses!$B$5/12,0),1)) -> 500 | J33: =H33+I33 -> 500 | K33: Estimation, 2 sessions pour les morceaux phares.
A34: Tests utilisateurs
A35: Tests utilisateurs | B35: Bons cadeaux pour testeurs | C35: 20 | D35: € | E35: Unique | F35: 15 | G35: 10 | H35: =$C35*IF($D35="$",Hypothèses!$B$6,1)*$F35*IF($E35="Mensuel",Hypothèses!$B$4,IF($E35="Annuel",ROUNDUP(Hypothèses!$B$4/12,0),1)) -> 300 | I35: =$C35*IF($D35="$",Hypothèses!$B$6,1)*$G35*IF($E35="Mensuel",Hypothèses!$B$5,IF($E35="Annuel",ROUNDUP(Hypothèses!$B$5/12,0),1)) -> 200 | J35: =H35+I35 -> 500 | K35: Hypothèse : 15 testeurs en phase 1, 10 en phase 2.
A36: Marketing & acquisition
A37: Marketing & acquisition | B37: Site vitrine (hébergement et outil) | C37: 15 | D37: € | E37: Mensuel | F37: 1 | G37: 1 | H37: =$C37*IF($D37="$",Hypothèses!$B$6,1)*$F37*IF($E37="Mensuel",Hypothèses!$B$4,IF($E37="Annuel",ROUNDUP(Hypothèses!$B$4/12,0),1)) -> 90 | I37: =$C37*IF($D37="$",Hypothèses!$B$6,1)*$G37*IF($E37="Mensuel",Hypothèses!$B$5,IF($E37="Annuel",ROUNDUP(Hypothèses!$B$5/12,0),1)) -> 180 | J37: =H37+I37 -> 270 | K37: Estimation.
A38: Marketing & acquisition | B38: Publicités TikTok / Instagram (tests) | C38: 300 | D38: € | E38: Unique | F38: 1 | G38: 0 | H38: =$C38*IF($D38="$",Hypothèses!$B$6,1)*$F38*IF($E38="Mensuel",Hypothèses!$B$4,IF($E38="Annuel",ROUNDUP(Hypothèses!$B$4/12,0),1)) -> 300 | I38: =$C38*IF($D38="$",Hypothèses!$B$6,1)*$G38*IF($E38="Mensuel",Hypothèses!$B$5,IF($E38="Annuel",ROUNDUP(Hypothèses!$B$5/12,0),1)) -> 0 | J38: =H38+I38 -> 300 | K38: Hypothèse : test de messages avant lancement.
A39: Marketing & acquisition | B39: Publicités TikTok / Instagram (lancement) | C39: 500 | D39: € | E39: Mensuel | F39: 0 | G39: 1 | H39: =$C39*IF($D39="$",Hypothèses!$B$6,1)*$F39*IF($E39="Mensuel",Hypothèses!$B$4,IF($E39="Annuel",ROUNDUP(Hypothèses!$B$4/12,0),1)) -> 0 | I39: =$C39*IF($D39="$",Hypothèses!$B$6,1)*$G39*IF($E39="Mensuel",Hypothèses!$B$5,IF($E39="Annuel",ROUNDUP(Hypothèses!$B$5/12,0),1)) -> 6000 | J39: =H39+I39 -> 6000 | K39: Hypothèse, à ajuster selon le coût d'acquisition mesuré.
A40: Marketing & acquisition | B40: Goodies et stickers Tic | C40: 200 | D40: € | E40: Unique | F40: 0 | G40: 1 | H40: =$C40*IF($D40="$",Hypothèses!$B$6,1)*$F40*IF($E40="Mensuel",Hypothèses!$B$4,IF($E40="Annuel",ROUNDUP(Hypothèses!$B$4/12,0),1)) -> 0 | I40: =$C40*IF($D40="$",Hypothèses!$B$6,1)*$G40*IF($E40="Mensuel",Hypothèses!$B$5,IF($E40="Annuel",ROUNDUP(Hypothèses!$B$5/12,0),1)) -> 200 | J40: =H40+I40 -> 200 | K40: Estimation, événements et partenaires.
...
